Workbook
Name tgr: DCF!$E$19
Name wacc: DCF!$E$18

Sheet Agenda
A4: x | B4: Agenda
A6: x | B6: The Bull Case
B7: 1. AI and data center expansion positions the company well for continued growth
B8: 2. Dominant position in the gaming GPU market ensures a steady revenue stream
B9: 3. Advancements in autonomous driving and edge computing present growth opportunities
A11: x | B11: The Bear Case
B12: 1. Supply chain issues could affect ability to meet demand
B13: 2. Intense competition from companies like AMD could impact market share and profitability
B14: 3. High valuation concerns

Sheet DCF
B2: NVIDIA DCF
B4: Ticker | D4: NVDA | F4: Implied Price Per Share | J4: =S83 -> 292.3799
B5: Date | D5: 46161 | F5: Current Share Price | J5: 220.61
B6: Year end | D6: 46053 | F6: Implied Upside / (Downside) | J6: =J4/J5-1 -> 0.32532478
A8: x | B8: Assumptions
B10: Switches | G10: Conservative | L10: Base | Q10: Optimistic
B11: Assumptions | G11: Assumptions | I11: Year | J11: Metric | L11: Assumptions | N11: Year | O11: Metric | Q11: Assumptions | S11: Year | T11: Metric
B12: Revenue | E12: 3 | G12: Revenue | I12: '27 | J12: -0.05 | L12: Revenue | N12: '27 | Q12: Revenue | S12: '27 | T12: 0.1
B13: EBIT | E13: 3 | G13: Revenue | I13: '28-'31 | J13: -0.35 | L13: Revenue | N13: '28-'31 | O13: -0.3 | Q13: Revenue | S13: '28-'31 | T13: -0.25
B14: WACC | E14: 3 | G14: EBIT | I14: '27 | J14: 0.03 | Q14: EBIT | S14: '27 | T14: 0.025
B15: TGR | E15: 3 | G15: EBIT | I15: '28-'31 | J15: 0.5 | Q15: EBIT | S15: '28-'31 | T15: 0.68
B17: Valuation
B18: WACC | E18: =CHOOSE(E14,J18,O18,T18) -> 0.12 | G18: WACC | J18: 0.16 | L18: WACC | O18: =WACC!F22 -> 0.14366693 | Q18: WACC | T18: 0.12
B19: TGR | E19: =CHOOSE(E15,J19,O19,T19) -> 0.03 | G19: TGR | J19: 0.02 | L19: TGR | O19: 0.025 | Q19: TGR | T19: 0.03
A21: x | B21: Income Statement (12/31 CYE) | E21: 2017 | F21: =E21+1 -> 2018 | G21: =F21+1 -> 2019 | H21: =G21+1 -> 2020 | I21: =H21+1 -> 2021 | J21: =I21+1 -> 2022 | K21: =J21+1 -> 2023 | L21: =K21+1 -> 2024 | M21: =L21+1 -> 2025 | ... S21: =R21+1 -> 2031
B22: Revenue | E22: =IS!F10 -> 6910 | F22: =IS!G10 -> 9714 | G22: =IS!H10 -> 11716 | H22: =IS!I10 -> 10918 | I22: =IS!J10 -> 16675 | J22: =IS!K10 -> 26914 | K22: =IS!L10 -> 26974 | L22: =IS!M10 -> 60922 | ... N22: =IS!O10 -> 215938 | O22: =N22*(O23+1) -> 374504.6 | P22: =O22*(P23+1) -> 658518.36 | Q22: =P22*(Q23+1) -> 1257506.9 | R22: =Q22*(R23+1) -> 2313575.6 | S22: =R22*(S23+1) -> 4116699.8
B23: % growth | E23: -- | F23: =F22/E22-1 -> 0.40578871 | G23: =G22/F22-1 -> 0.2060943 | H23: =H22/G22-1 -> -0.068111984 | I23: =I22/H22-1 -> 0.52729438 | J23: =J22/I22-1 -> 0.61403298 | K23: =K22/J22-1 -> 0.002229323 | L23: =L22/K22-1 -> 1.2585453 | M23: =M22/L22-1 -> 1.1420341 | N23: =N22/M22-1 -> 0.65473536 | O23: =AVERAGE(J23:N23) -> 0.7343154 | P23: =AVERAGE(K23:O23) -> 0.75837188 | Q23: =AVERAGE(L23:P23) -> 0.9096004 | R23: =AVERAGE(M23:Q23) -> 0.83981142 | S23: =AVERAGE(N23:R23) -> 0.77936689
B25: EBIT | E25: =IS!F27 -> 1934 | F25: =IS!G27 -> 3210 | G25: =IS!H27 -> 3804 | H25: =IS!I27 -> 2846 | I25: =IS!J27 -> 4532 | J25: =IS!K27 -> 10041 | K25: =IS!L27 -> 4224 | L25: =IS!M27 -> 32972 | ... N25: =IS!O27 -> 130387 | O25: =O26*O22 -> 220858.94 | P25: =P26*P22 -> 331305.88 | Q25: =Q26*Q22 -> 719810.3 | R25: =R26*R22 -> 1338749.1 | S25: =S26*S22 -> 2344642.6
B26: % of sales | E26: =E25/E22 -> 0.27988423 | F26: =F25/F22 -> 0.3304509 | G26: =G25/G22 -> 0.32468419 | H26: =H25/H22 -> 0.26067045 | I26: =I25/I22 -> 0.27178411 | J26: =J25/J22 -> 0.37307721 | K26: =K25/K22 -> 0.15659524 | L26: =L25/L22 -> 0.54121664 | ... N26: =N25/N22 -> 0.60381684 | O26: =AVERAGE(L26:N26) -> 0.58973625 | P26: =AVERAGE(K26:O26) -> 0.50310805 | Q26: =AVERAGE(L26:P26) -> 0.57241061 | R26: =AVERAGE(M26:Q26) -> 0.5786494 | S26: =AVERAGE(N26:R26) -> 0.56954423
B28: Taxes | E28: =IS!F20 -> 239 | F28: =IS!G20 -> 149 | G28: =IS!H20 -> -245 | H28: =IS!I20 -> 174 | I28: =IS!J20 -> 77 | J28: =IS!K20 -> 189 | K28: =IS!L20 -> -187 | L28: =IS!M20 -> 4058 | ... N28: =IS!O20 -> 21383 | O28: =O25*O29 -> 33128.841 | P28: =P25*P29 -> 49695.883 | Q28: =Q25*Q29 -> 107971.54 | R28: =R25*R29 -> 200812.37 | S28: =S25*S29 -> 351696.39
B29: Tax rate | E29: =E28/E25 -> 0.12357808 | F29: =F28/F25 -> 0.046417445 | G29: =G28/G25 -> -0.064405889 | H29: =H28/H25 -> 0.06113844 | I29: =I28/I25 -> 0.016990291 | J29: =J28/J25 -> 0.018822826 | K29: =K28/K25 -> -0.044270833 | L29: =L28/L25 -> 0.12307412 | ... N29: =N28/N25 -> 0.16399641 | O29: 0.15 | P29: 0.15 | Q29: 0.15 | R29: 0.15 | S29: 0.15
A31: x | B31: Cash Flow Items (12/31 CYE) | E31: =E21 -> 2017 | F31: =F21 -> 2018 | G31: =G21 -> 2019 | H31: =H21 -> 2020 | I31: =I21 -> 2021 | J31: =J21 -> 2022 | K31: =K21 -> 2023 | L31: =L21 -> 2024 | M31: =M21 -> 2025 | N31: =M31+1 -> 2026 | O31: =N31+1 -> 2027 | P31: =O31+1 -> 2028 | Q31: =P31+1 -> 2029 | R31: =Q31+1 -> 2030 | S31: =R31+1 -> 2031
B32: D&A | E32: =CFS!F12 -> 187 | F32: =CFS!G12 -> 199 | G32: =CFS!H12 -> 262 | H32: =CFS!I12 -> 381 | I32: =CFS!J12 -> 1098 | J32: =CFS!K12 -> 1174 | K32: =CFS!L12 -> 1544 | L32: =CFS!M12 -> 1508 | ... N32: =CFS!O12 -> 2843 | O32: =O22*O33 -> 11464.586 | P32: =P22*P33 -> 18445.838 | Q32: =Q22*Q33 -> 27872.999 | R32: =R22*R33 -> 50083.705 | S32: =S22*S33 -> 95180.277
B33: % of sales | E33: =E32/E22 -> 0.027062229 | F33: =F32/F22 -> 0.020485897 | G33: =G32/G22 -> 0.022362581 | H33: =H32/H22 -> 0.034896501 | I33: =I32/I22 -> 0.065847076 | J33: =J32/J22 -> 0.043620421 | K33: =K32/K22 -> 0.057240305 | L33: =L32/L22 -> 0.024752963 | ... N33: =N32/N22 -> 0.013165816 | O33: =AVERAGE(J33:N33) -> 0.030612672 | P33: =AVERAGE(K33:O33) -> 0.028011122 | Q33: =AVERAGE(L33:P33) -> 0.022165285 | R33: =AVERAGE(M33:Q33) -> 0.02164775 | S33: =AVERAGE(N33:R33) -> 0.023120529
B35: CapEx | E35: =-CFS!F21 -> 169 | F35: =-CFS!G21 -> 591 | G35: =-CFS!H21 -> 600 | H35: =-CFS!I21 -> 489 | I35: =-CFS!J21 -> 1128 | J35: =-CFS!K21 -> 976 | K35: =-CFS!L21 -> 1833 | L35: =-CFS!M21 -> 1069 | ... N35: =-CFS!O21 -> 6042 | O35: =O22*O36 -> 13073.414 | P35: =P22*P36 -> 22809.451 | Q35: =Q22*Q36 -> 35177.718 | R35: =R22*R36 -> 69545.166 | S35: =S22*S36 -> 128078.86
B36: % of sales | E36: =E35/E22 -> 0.024457308 | F36: =F35/F22 -> 0.060840025 | G36: =G35/G22 -> 0.051212018 | H36: =H35/H22 -> 0.044788423 | I36: =I35/I22 -> 0.067646177 | J36: =J35/J22 -> 0.036263655 | K36: =K35/K22 -> 0.067954326 | L36: =L35/L22 -> 0.017547027 | ... N36: =N35/N22 -> 0.027980254 | O36: =AVERAGE(J36:N36) -> 0.034908553 | P36: =AVERAGE(K36:O36) -> 0.034637533 | Q36: =AVERAGE(L36:P36) -> 0.027974174 | R36: =AVERAGE(M36:Q36) -> 0.030059604 | S36: =AVERAGE(N36:R36) -> 0.031112024
B38: Change in NWC | E38: =-CFS!F19 -> 530 | F38: =-CFS!G19 -> 329 | G38: =-CFS!H19 -> 1113 | H38: =-CFS!I19 -> -663 | I38: =-CFS!J19 -> 993 | J38: =-CFS!K19 -> 3944 | K38: =-CFS!L19 -> 3548 | L38: =-CFS!M19 -> 5747 | ... N38: =-CFS!O19 -> 21206 | O38: =O22*O39 -> 43090.286 | P38: =P22*P39 -> 71622.531 | Q38: =Q22*Q39 -> 131043.5 | R38: =R22*R39 -> 245664.74 | S38: =S22*S39 -> 438362.39
B39: % of sales | E39: =E38/E22 -> 0.076700434 | F39: =F38/F22 -> 0.033868643 | G39: =G38/G22 -> 0.094998293 | H39: =H38/H22 -> -0.060725408 | I39: =I38/I22 -> 0.059550225 | J39: =J38/J22 -> 0.14654083 | K39: =K38/K22 -> 0.13153407 | L39: =L38/L22 -> 0.094333738 | ... N39: =N38/N22 -> 0.098204114 | O39: =AVERAGE(J39:N39) -> 0.11505943 | P39: =AVERAGE(K39:O39) -> 0.10876315 | Q39: =AVERAGE(L39:P39) -> 0.10420897 | R39: =AVERAGE(M39:Q39) -> 0.10618401 | S39: =AVERAGE(N39:R39) -> 0.10648393
O41: 1 | P41: =O41+1 -> 2 | Q41: =P41+1 -> 3 | R41: =Q41+1 -> 4 | S41: =R41+1 -> 5
A42: x | B42: DCF | E42: =E31 -> 2017 | F42: =E42+1 -> 2018 | G42: =F42+1 -> 2019 | H42: =G42+1 -> 2020 | I42: =H42+1 -> 2021 | J42: =I42+1 -> 2022 | K42: =J42+1 -> 2023 | L42: =K42+1 -> 2024 | M42: =L42+1 -> 2025 | ... S42: =R42+1 -> 2031
B43: Revenue | E43: =E22 -> 6910 | F43: =F22 -> 9714 | G43: =G22 -> 11716 | H43: =H22 -> 10918 | I43: =I22 -> 16675 | J43: =J22 -> 26914 | K43: =K22 -> 26974 | L43: =L22 -> 60922 | ... N43: =N22 -> 215938 | O43: =N43*(1+O44) -> 390361.26 | P43: =O43*(1+P44) -> 545781.74 | Q43: =P43*(1+Q44) -> 806414.46 | R43: =Q43*(1+R44) -> 1161963.4 | S43: =R43*(1+S44) -> 1637401.2
B44: % growth | E44: -- | F44: =F43/E43-1 -> 0.40578871 | G44: =G43/F43-1 -> 0.2060943 | H44: =H43/G43-1 -> -0.068111984 | I44: =I43/H43-1 -> 0.52729438 | J44: =J43/I43-1 -> 0.61403298 | K44: =K43/J43-1 -> 0.002229323 | L44: =L43/K43-1 -> 1.2585453 | M44: =M43/L43-1 -> 1.1420341 | N44: =N43/M43-1 -> 0.65473536 | O44: =OFFSET(O44,$E$12,0) -> 0.80774694 | P44: =OFFSET(P44,$E$12,0) -> 0.39814524 | Q44: =OFFSET(Q44,$E$12,0) -> 0.47754021 | R44: =OFFSET(R44,$E$12,0) -> 0.440901 | S44: =OFFSET(S44,$E$12,0) -> 0.40916762
B45: Conservative Case | O45: =O46*(1+$J$12) -> 0.69759963 | P45: =P46*(1+$J$13) -> 0.34505921 | Q45: =Q46*(1+$J$13) -> 0.41386818 | R45: =R46*(1+$J$13) -> 0.3821142 | S45: =S46*(1+$J$13) -> 0.35461194
B46: Base Case | O46: =O23 -> 0.7343154 | P46: =P23*(1+$O$13) -> 0.53086032 | Q46: =Q23*(1+$O$13) -> 0.63672028 | R46: =R23*(1+$O$13) -> 0.587868 | S46: =S23*(1+$O$13) -> 0.54555683
B47: Optimistic Case | O47: =O46*(1+$T$12) -> 0.80774694 | P47: =P46*(1+$T$13) -> 0.39814524 | Q47: =Q46*(1+$T$13) -> 0.47754021 | R47: =R46*(1+$T$13) -> 0.440901 | S47: =S46*(1+$T$13) -> 0.40916762
B49: EBIT | E49: =E25 -> 1934 | F49: =F25 -> 3210 | G49: =G25 -> 3804 | H49: =H25 -> 2846 | I49: =I25 -> 4532 | J49: =J25 -> 10041 | K49: =K25 -> 4224 | L49: =L25 -> 32972 | ... N49: =N25 -> 130387 | O49: =O43*O50 -> 241599.37 | P49: =P43*P50 -> 346126.15 | Q49: =Q43*Q50 -> 523730.81 | R49: =R43*R50 -> 772389.68 | S49: =S43*S50 -> 1113432.8
B50: % of sales | E50: =E49/E43 -> 0.27988423 | F50: =F49/F43 -> 0.3304509 | G50: =G49/G43 -> 0.32468419 | H50: =H49/H43 -> 0.26067045 | I50: =I49/I43 -> 0.27178411 | J50: =J49/J43 -> 0.37307721 | K50: =K49/K43 -> 0.15659524 | L50: =L49/L43 -> 0.54121664 | ... N50: =N49/N43 -> 0.60381684 | O50: =OFFSET(O50,$E$13:$E$13,0) -> 0.61891226 | P50: =OFFSET(P50,$E$13:$E$13,0) -> 0.63418419 | Q50: =OFFSET(Q50,$E$13:$E$13,0) -> 0.64945613 | R50: =OFFSET(R50,$E$13:$E$13,0) -> 0.66472806 | S50: =OFFSET(S50,$E$13:$E$13,0) -> 0.68
B51: Conservative Case | O51: =O52*(1+$J$14) -> 0.62193134 | P51: =O51+($S$51-$O$51)/($S$42-$O$42) -> 0.59144851 | Q51: =P51+($S$51-$O$51)/($S$42-$O$42) -> 0.56096567 | R51: =Q51+($S$51-$O$51)/($S$42-$O$42) -> 0.53048284 | S51: =J15 -> 0.5
B52: Base Case | O52: =N26 -> 0.60381684 | P52: =O52 -> 0.60381684 | Q52: =P52 -> 0.60381684 | R52: =Q52 -> 0.60381684 | S52: =R52 -> 0.60381684
B53: Optimistic Case | O53: =O52*(1+$T$14) -> 0.61891226 | P53: =O53+($S$53-$O$53)/($S$42-$O$42) -> 0.63418419 | Q53: =P53+($S$53-$O$53)/($S$42-$O$42) -> 0.64945613 | R53: =Q53+($S$53-$O$53)/($S$42-$O$42) -> 0.66472806 | S53: =T15 -> 0.68
...

Sheet WACC
B2: WACC
B4: WACC = % of equity x cost of equity + % of debt x cost of debt x (1 - Tax Rate)
B5: Cost of equity = Risk free rate + Beta x Market Risk Premium
A7: x | B7: WACC
B8: Market Cap | F8: 4943000 | G8: Companies market cap
B9: % of Equity | F9: =F8/(F8+F15) -> 0.9982898
B10: Cost of Equity | F10: =F11+F12*F13 -> 0.14387
B11: Risk Free Rate | F11: 0.04575 | G11: Trading Economics
B12: Beta | F12: 2.2 | G12: Yahoo finance
B13: Market Risk Premium | F13: 0.0446 | G13: Damodoran
B15: Debt | F15: 8468 | G15: Nvidia report
B16: % of Debt | F16: =F15/(F8+F15) -> 0.0017101999
B17: Cost of Debt | F17: 0.0296
B18: Tax Rate | F18: =DCF!O56 -> 0.151
B20: Total | F20: =F8+F15 -> 4951468
A22: x | B22: WACC | F22: =F9*F10+(F16*F17*(1-F18)) -> 0.14366693

Sheet IS
A1: NVIDIA Corporation (NVDA)
A2: $949.50
A5: NVIDIA Corporation
A6: NVDA 67066G104 2379504 NASDAQ Common stock
A7: Source: Macrotrends | B7: 41305 | C7: 41670 | D7: 42035 | E7: 42400 | F7: 42766 | G7: 43131 | H7: 43496 | I7: 43861 | J7: 44227 | K7: 44592 | L7: 44957 | M7: 45322 | N7: 45688 | O7: 46053
B8: 2013 | C8: =B8+1 -> 2014 | D8: =C8+1 -> 2015 | E8: =D8+1 -> 2016 | F8: =E8+1 -> 2017 | G8: =F8+1 -> 2018 | H8: =G8+1 -> 2019 | I8: =H8+1 -> 2020 | J8: =I8+1 -> 2021 | ... O8: =N8+1 -> 2026
B9: ="FY ' "&RIGHT(B8,2) -> FY ' 13 | C9: ="FY ' "&RIGHT(C8,2) -> FY ' 14 | D9: ="FY ' "&RIGHT(D8,2) -> FY ' 15 | E9: ="FY ' "&RIGHT(E8,2) -> FY ' 16 | F9: ="FY ' "&RIGHT(F8,2) -> FY ' 17 | G9: ="FY ' "&RIGHT(G8,2) -> FY ' 18 | H9: ="FY ' "&RIGHT(H8,2) -> FY ' 19 | I9: ="FY ' "&RIGHT(I8,2) -> FY ' 20 | ... O9: ="FY ' "&RIGHT(O8,2) -> FY ' 26
A10: Revenue | B10: 4280.159 | C10: 4130 | D10: 4682 | E10: 5010 | F10: 6910 | G10: 9714 | H10: 11716 | I10: 10918 | J10: 16675 | K10: 26914 | L10: 26974 | M10: 60922 | N10: 130497 | O10: 215938
A11: Cost Of Goods Sold | B11: 2053.816 | C11: 1862 | D11: 2083 | E11: 2199 | F11: 2847 | G11: 3892 | H11: 4545 | I11: 4150 | J11: 6279 | K11: 9439 | L11: 11618 | M11: 16621 | N11: 32639 | O11: 62475
A12: Gross Profit | B12: 2226.343 | C12: 2268 | D12: 2599 | E12: 2811 | F12: 4063 | G12: 5822 | H12: 7171 | I12: 6768 | J12: 10396 | K12: 17475 | L12: 15356 | M12: 44301 | N12: 97858 | O12: 153463
A13: R&D Expenses | B13: 1147.282 | C13: 1336 | D13: 1360 | E13: 1331 | F13: 1463 | G13: 1797 | H13: 2376 | I13: 2829 | J13: 3924 | K13: 5268 | L13: 7339 | M13: 8675 | N13: 12914 | O13: 18497
A14: SG&A Expenses | B14: 430.822 | C14: 436 | D14: 480 | E14: 602 | F14: 663 | G14: 815 | H14: 991 | I14: 1093 | J14: 1940 | K14: 2166 | L14: 2440 | M14: 2654 | N14: 3491 | O14: 4579
A15: Other Operating Income/Expenses | B15: 0 | C15: 0 | D15: 0 | E15: 0 | F15: 0 | G15: 0 | H15: 0 | I15: 0 | J15: 0 | K15: 0 | L15: 0 | M15: 0 | N15: 0 | O15: 0
A16: Operating Expenses | B16: 1578.104 | C16: 1772 | D16: 1840 | E16: 2064 | F16: 2129 | G16: 2612 | H16: 3367 | I16: 3922 | J16: 5864 | K16: 7434 | L16: 11132 | M16: 11329 | N16: 16405 | O16: 23076
A17: Operating Income | B17: 648.239 | C17: 496 | D17: 759 | E17: 747 | F17: 1934 | G17: 3210 | H17: 3804 | I17: 2846 | J17: 4532 | K17: 10041 | L17: 4224 | M17: 32972 | N17: 81453 | O17: 130387
A18: Total Non-Operating Income/Expense | B18: 13.8 | C18: 14 | D18: -4 | E18: -4 | F18: -29 | G18: -14 | H18: 92 | I18: 124 | J18: -123 | K18: -100 | L18: -43 | M18: 846 | N18: 2573 | O18: 11063
A19: Pre-Tax Income | B19: 662.039 | C19: 510 | D19: 755 | E19: 743 | F19: 1905 | G19: 3196 | H19: 3896 | I19: 2970 | J19: 4409 | K19: 9941 | L19: 4181 | M19: 33818 | N19: 84026 | O19: 141450
A20: Income Taxes | B20: 99.503 | C20: 70 | D20: 124 | E20: 129 | F20: 239 | G20: 149 | H20: -245 | I20: 174 | J20: 77 | K20: 189 | L20: -187 | M20: 4058 | N20: 11146 | O20: 21383
A21: Income After Taxes | B21: 562.536 | C21: 440 | D21: 631 | E21: 614 | F21: 1666 | G21: 3047 | H21: 4141 | I21: 2796 | J21: 4332 | K21: 9752 | L21: 4368 | M21: 29760 | N21: 72880 | O21: 120067
... A31: EPS - Diluted | B31: 0.02 | C31: 0.02 | D31: 0.03 | E31: 0.03 | F31: 0.06 | G31: 0.12 | H31: 0.17 | I31: 0.11 | J31: 0.17 | K31: 0.39 | L31: 0.17 | M31: 1.19 | N31: 2.94 | O31: 4.9
A32: All figures in millions of U.S. Dollar except per share items.

Sheet CFS
A1: NVIDIA Corporation (NVDA)
A2: $949.50
A5: NVIDIA Corporation
A6: NVDA 67066G104 2379504 NASDAQ Common stock
A7: Source: Macrotrends
B8: 2013 | C8: =B8+1 -> 2014 | D8: =C8+1 -> 2015 | E8: =D8+1 -> 2016 | F8: =E8+1 -> 2017 | G8: =F8+1 -> 2018 | H8: =G8+1 -> 2019 | I8: =H8+1 -> 2020 | J8: =I8+1 -> 2021 | ... O8: =N8+1 -> 2026
B9: ="FY ' "&RIGHT(B8,2) -> FY ' 13 | C9: ="FY ' "&RIGHT(C8,2) -> FY ' 14 | D9: ="FY ' "&RIGHT(D8,2) -> FY ' 15 | E9: ="FY ' "&RIGHT(E8,2) -> FY ' 16 | F9: ="FY ' "&RIGHT(F8,2) -> FY ' 17 | G9: ="FY ' "&RIGHT(G8,2) -> FY ' 18 | H9: ="FY ' "&RIGHT(H8,2) -> FY ' 19 | I9: ="FY ' "&RIGHT(I8,2) -> FY ' 20 | ... O9: ="FY ' "&RIGHT(O8,2) -> FY ' 26
A10: Metric | B10: 41305 | C10: 41670 | D10: 42035 | E10: 42400 | F10: 42766 | G10: 43131 | H10: 43496 | I10: 43861 | J10: 44227 | K10: 44592 | L10: 44957 | M10: 45322 | N10: 45688 | O10: 46053
A11: Net Income/Loss | B11: 562.536 | C11: 440 | D11: 631 | E11: 614 | F11: 1666 | G11: 3047 | H11: 4141 | I11: 2796 | J11: 4332 | K11: 9752 | L11: 4368 | M11: 29760 | N11: 72880 | O11: 120067
A12: Total D&A - Cash Flow | B12: 226.235 | C12: 244 | D12: 248 | E12: 226 | F12: 187 | G12: 199 | H12: 262 | I12: 381 | J12: 1098 | K12: 1174 | L12: 1544 | M12: 1508 | N12: 1864 | O12: 2843
A13: Other Non-Cash Items | B13: 168.864 | C13: 138 | D13: 230 | E13: 386 | F13: 498 | G13: 71 | H13: 197 | I13: 867 | J13: 1095 | K13: 1545 | L13: 1936 | M13: 544 | N13: -1272 | O13: -4243
A14: Total Non-Cash Items | B14: 395.099 | C14: 382 | D14: 478 | E14: 612 | F14: 685 | G14: 270 | H14: 459 | I14: 1248 | J14: 2193 | K14: 2719 | L14: 3480 | M14: 2052 | N14: 592 | O14: -1400
A15: Change In Accounts Receivable | B15: -118.94 | C15: 29 | D15: -49 | E15: -32 | F15: -321 | G15: -440 | H15: -149 | I15: -233 | J15: -550 | K15: -2215 | L15: 822 | M15: -6172 | N15: -13063 | O15: -15399
A16: Change In Inventories | B16: -78.949 | C16: 25 | D16: -95 | E16: 66 | F16: -375 | G16: 0 | H16: -776 | I16: 597 | J16: -524 | K16: -774 | L16: -2554 | M16: -98 | N16: -4781 | O16: -11324
A17: Change In Accounts Payable | B17: 10.885 | C17: -20 | D17: -27 | E17: -11 | F17: 184 | G17: 90 | H17: -135 | I17: 194 | J17: 312 | K17: 568 | L17: -551 | M17: 1531 | N17: 3357 | O17: 3096
A18: Change In Assets/Liabilities | B18: 36.188 | C18: 12 | D18: 4 | E18: -16 | F18: -18 | G18: 21 | H18: -53 | I18: 105 | J18: -231 | K18: -1523 | L18: -1265 | M18: -1008 | N18: 826 | O18: 2421
A19: Total Change In Assets/Liabilities | B19: =SUM(B15:B18) -> -150.816 | C19: =SUM(C15:C18) -> 46 | D19: =SUM(D15:D18) -> -167 | E19: =SUM(E15:E18) -> 7 | F19: =SUM(F15:F18) -> -530 | G19: =SUM(G15:G18) -> -329 | H19: =SUM(H15:H18) -> -1113 | I19: =SUM(I15:I18) -> 663 | ... O19: =SUM(O15:O18) -> -21206
A20: Cash Flow From Operating Activities | B20: 824.172 | C20: 835 | D20: 906 | E20: 1175 | F20: 1672 | G20: 3502 | H20: 3743 | I20: 4761 | J20: 5822 | K20: 9108 | L20: 5641 | M20: 28090 | N20: 64089 | O20: 102718
A21: Net Change In PP&E | B21: -183.309 | C21: -230 | D21: -101 | E21: -79 | F21: -169 | G21: -591 | H21: -600 | I21: -489 | J21: -1128 | K21: -976 | L21: -1833 | M21: -1069 | N21: -3236 | O21: -6042
A22: Net Change In Intangible Assets | B22: 0 | C22: 0 | D22: 0 | E22: 0 | F22: 0 | G22: 0 | H22: 0 | I22: 0 | J22: 0 | K22: 0 | L22: 0 | M22: 0 | N22: 0 | O22: 0
A23: Net Acquisitions/Divestitures | B23: 0 | C23: -17 | D23: 0 | E23: 0 | F23: 0 | G23: 0 | H23: 0 | I23: -4 | J23: -8524 | K23: -263 | L23: -49 | M23: -83 | N23: -1007 | O23: -1535
A24: Net Change In Short-term Investments | B24: -561.035 | C24: -554 | D24: -625 | E24: -345 | F24: -624 | G24: 1869 | H24: -3488 | I24: 6648 | J24: -9989 | K24: -8591 | L24: 9334 | M24: -8429 | N24: -14885 | O24: -14233
A25: Net Change In Long-Term Investments | B25: 0 | C25: 0 | D25: 0 | E25: 0 | F25: 0 | G25: 0 | H25: 0 | I25: 0 | J25: 0 | K25: 0 | L25: -77 | M25: -861 | N25: -1315 | O25: -17418
A26: Net Change In Investments - Total | B26: -561.035 | C26: -554 | D26: -625 | E26: -345 | F26: -624 | G26: 1869 | H26: -3488 | I26: 6648 | J26: -9989 | K26: -8591 | L26: 9257 | M26: -9290 | N26: -16200 | O26: -31651
A27: Investing Activities - Other | B27: 0.352 | C27: -5 | D27: -1 | E27: 24 | F27: 0 | G27: 0 | H27: -9 | I27: 0 | J27: -10 | K27: -34 | L27: 0 | M27: -124 | N27: 22 | O27: -13000
A28: Cash Flow From Investing Activities | B28: -743.992 | C28: -806 | D28: -727 | E28: -400 | F28: -793 | G28: 1278 | H28: -4097 | I28: 6145 | J28: -19675 | K28: -9830 | L28: 7375 | M28: -10566 | N28: -20421 | O28: -52228
A29: Net Long-Term Debt | B29: -2.049 | C29: 1309 | D29: 0 | E29: 0 | F29: 1988 | G29: 0 | H29: 0 | I29: 0 | J29: 4968 | K29: 3977 | L29: 0 | M29: -1250 | N29: -1250 | O29: 0
A30: Net Current Debt | B30: 0 | C30: 0 | D30: 0 | E30: 0 | F30: -673 | G30: -812 | H30: -16 | I30: 0 | J30: 0 | K30: 0 | L30: 0 | M30: 0 | N30: 0 | O30: 0
A31: Debt Issuance/Retirement Net - Total | B31: -2.049 | C31: 1309 | D31: 0 | E31: 0 | F31: 1315 | G31: -812 | H31: -16 | I31: 0 | J31: 4968 | K31: 3977 | L31: 0 | M31: -1250 | N31: -1250 | O31: 0
... A38: Stock-Based Compensation | B38: 136.662 | C38: 136 | D38: 158 | E38: 204 | F38: 247 | G38: 391 | H38: 557 | I38: 844 | J38: 1397 | K38: 2004 | L38: 2709 | M38: 3549 | N38: 4737 | O38: 6386
A60: All figures in millions of U.S. Dollar except per share items.
